[2021-04-20 07:02:20,432] {taskinstance.py:655} INFO - Dependencies all met for <TaskInstance: global_dag.upload_file 2018-11-01T00:00:00+00:00 [queued]>
[2021-04-20 07:02:20,468] {taskinstance.py:655} INFO - Dependencies all met for <TaskInstance: global_dag.upload_file 2018-11-01T00:00:00+00:00 [queued]>
[2021-04-20 07:02:20,469] {taskinstance.py:866} INFO - 
--------------------------------------------------------------------------------
[2021-04-20 07:02:20,470] {taskinstance.py:867} INFO - Starting attempt 1 of 4
[2021-04-20 07:02:20,471] {taskinstance.py:868} INFO - 
--------------------------------------------------------------------------------
[2021-04-20 07:02:20,555] {taskinstance.py:887} INFO - Executing <Task(UploadFileOperator): upload_file> on 2018-11-01T00:00:00+00:00
[2021-04-20 07:02:20,560] {standard_task_runner.py:53} INFO - Started process 3237 to run task
[2021-04-20 07:02:20,666] {logging_mixin.py:112} INFO - Running %s on host %s <TaskInstance: global_dag.upload_file 2018-11-01T00:00:00+00:00 [running]> 68b6afff5d68
[2021-04-20 07:02:20,732] {upload_file.py:61} INFO - Uploading file to S3.
[2021-04-20 07:02:22,305] {taskinstance.py:1128} ERROR - [Errno 2] No such file or directory: '/usr/local/airflow/output/2021/sales.json'
Traceback (most recent call last):
  File "/usr/local/lib/python3.7/site-packages/airflow/models/taskinstance.py", line 966, in _run_raw_task
    result = task_copy.execute(context=context)
  File "/usr/local/airflow/plugins/operators/upload_file.py", line 64, in execute
    aws_secret_access_key=credentials.secret_key
  File "/usr/local/airflow/plugins/operators/upload_file.py", line 52, in upload_file
    response = s3_client.upload_file(self.path_to_file, self.S3_bucket, object_name, ExtraArgs=ACL)
  File "/usr/local/airflow/.local/lib/python3.7/site-packages/boto3/s3/inject.py", line 131, in upload_file
    extra_args=ExtraArgs, callback=Callback)
  File "/usr/local/airflow/.local/lib/python3.7/site-packages/boto3/s3/transfer.py", line 279, in upload_file
    future.result()
  File "/usr/local/airflow/.local/lib/python3.7/site-packages/s3transfer/futures.py", line 106, in result
    return self._coordinator.result()
  File "/usr/local/airflow/.local/lib/python3.7/site-packages/s3transfer/futures.py", line 265, in result
    raise self._exception
  File "/usr/local/airflow/.local/lib/python3.7/site-packages/s3transfer/tasks.py", line 255, in _main
    self._submit(transfer_future=transfer_future, **kwargs)
  File "/usr/local/airflow/.local/lib/python3.7/site-packages/s3transfer/upload.py", line 549, in _submit
    upload_input_manager.provide_transfer_size(transfer_future)
  File "/usr/local/airflow/.local/lib/python3.7/site-packages/s3transfer/upload.py", line 237, in provide_transfer_size
    transfer_future.meta.call_args.fileobj))
  File "/usr/local/airflow/.local/lib/python3.7/site-packages/s3transfer/utils.py", line 245, in get_file_size
    return os.path.getsize(filename)
  File "/usr/local/lib/python3.7/genericpath.py", line 50, in getsize
    return os.stat(filename).st_size
FileNotFoundError: [Errno 2] No such file or directory: '/usr/local/airflow/output/2021/sales.json'
[2021-04-20 07:02:22,324] {taskinstance.py:1151} INFO - Marking task as UP_FOR_RETRY
[2021-04-20 07:02:30,331] {logging_mixin.py:112} INFO - [2021-04-20 07:02:30,331] {local_task_job.py:103} INFO - Task exited with return code 1
